{
 "cells": [
  {
   "cell_type": "code",
   "execution_count": 1,
   "metadata": {},
   "outputs": [
    {
     "data": {
      "text/html": [
       "﻿<STYLE>\r\n",
       " .tab_text { text-indent:40px; }\r\n",
       " .large_text { font-size:22px; }\r\n",
       " .larger_text { font-size:1em }\r\n",
       " .blue { color:#23AAFF; }\r\n",
       " .pink { color:#ebd3d7; }\r\n",
       " .green { color:green; }\r\n",
       " .stress_text { font-weight:bold }\r\n",
       " .bold_text { font-weight:bold; }\r\n",
       " .large_bold { font-size:16pt; font-weight:bold; color:#23AAFF; }\r\n",
       " .special { color:orange; font-weight:bold; }\r\n",
       " .header_2 { text-align:center; font-size:20px; }\r\n",
       " .header_4 { font-size:20px; color:green; text-indent:40px; }\r\n",
       " .header_6 { font-size:16px; font-weight:bold; color:gray }\r\n",
       "</STYLE>"
      ],
      "text/plain": [
       "<IPython.core.display.HTML object>"
      ]
     },
     "execution_count": 1,
     "metadata": {},
     "output_type": "execute_result"
    }
   ],
   "source": [
    "# стиль оформления документа\n",
    "from IPython.display import HTML\n",
    "from urllib.request import urlopen\n",
    "html = urlopen(\"file:lecture.css\")\n",
    "HTML(html.read().decode('utf-8'))"
   ]
  },
  {
   "cell_type": "markdown",
   "metadata": {},
   "source": [
    "<img src=../Img/banner.png>\n",
    "\n",
    "11 ноября 2022 года<br>\n",
    "Семинар, 15:40 - 17:10, 5-я пара<br>\n",
    "В4/3411(кк), 4-й Вешняковский проезд, 4<br>\n",
    "Группа БИ22-13\n",
    "\n",
    "Преподаватель: Смирнов Михаил Викторович, доцент Департамента Анализа данных и машинного обучения Финансового университета при Правительстве Российской Федерации\n",
    "<p style=\"font-size:150%; text-align:left\">Тема 5. Работа с файлами и обработка исключительных ситуаций</p>\n",
    "<p style=\"font-size:150%; text-align:left\">5.3. Обработка исключительных ситуаций</p>"
   ]
  },
  {
   "cell_type": "markdown",
   "metadata": {},
   "source": [
    "При подготовке занятия использованы материалы онлайн школы <a href=https://skillfactory.ru/> SkillFactory </a>\n",
    "\n",
    "<p class=\"tab_text large_text green\">Учебные вопросы</p>\n",
    "\n",
    "- ошибки и исключения в программе;\n",
    "- отладка программы;\n",
    "- тестирование программы.\n",
    "\n",
    "<p class=\"tab_text large_text green\">Задачи</p>\n",
    "\n",
    "- научиться обрабатывать ошибки;\n",
    "- эффективно устранять ошибки;\n",
    "- повысить устойчивость кода к ошибкам.\n",
    "\n",
    "<p class=\"large_text\" style=\"text-align:center\">1. Сообщения об ошибках</p>\n",
    "\n",
    "Программа — набор инструкций, которые мы отправляем интерпретатору. Когда интерпретатор не понимает наших инструкций, он сообщает об этом. Возникает сообщение об ошибке.\n",
    "\n",
    "Мы допустили синтаксическую ошибку и получили сообщение:\n",
    "\n",
    "```\n",
    "print(\"Привет!')\n",
    "    File \"<ipython-input-4-ebeda6125e45>\", line 1\n",
    "        print(\"hello')\n",
    "                  ^\n",
    "SyntaxError: EOL while scanning string literal\n",
    "```\n",
    "\n",
    "Обратите внимание:\n",
    "\n",
    "- Сообщение начинается с названия файла, где допущена ошибка. В примере это ячейка из Jupyter, поэтому название является техническим.\n",
    "- После названия файла идёт номер строки с ошибкой, в данном случае — первая строка (line 1).\n",
    "- Выводится конкретная строка из кода.\n",
    "- В конце указывается, что это была синтаксическая ошибка (SyntaxError), и идёт пояснительное сообщение. У разных синтаксических ошибок пояснительное сообщение разное и обычно позволяет понять, как исправить ошибку.\n",
    "\n",
    "Сообщение об ошибке удобно читать с конца.\n",
    "\n",
    "<p class=\"header_4\">Задание</p>\n",
    "\n",
    "Какой номер у строки с ошибкой, судя по этому сообщению?\n",
    "\n",
    "```\n",
    "File \"<ipython-input-273-806349a3f7cd>\", line 6\n",
    "    def street(street_name, last_house)\n",
    "                                       ^\n",
    "SyntaxError: invalid syntax\n",
    "```\n",
    "\n",
    "\n",
    "<p class=\"header_2\"> Исключения </p>\n",
    "\n",
    "**Синтаксические ошибки** исправлять проще всего: это опечатки, и даже если мы их допустили, часто они находятся в одной строчке, на которую нам указывает интерпретатор. Более интересный класс ошибок — неудачные сочетания логики и данных:\n",
    "\n",
    "```\n",
    "a=5/0\n",
    "----------------------------------------------------------------------\n",
    "ZeroDivisionError                    Traceback (most recent call last)\n",
    "<ipython-input-5-7ab028d636d0> in <module>\n",
    "----> 1 a=5/0\n",
    "\n",
    "ZeroDivisionError: division by zero\n",
    "```\n",
    "Мы стали делить на ноль, и Python вывел сообщение об ошибке:\n",
    "\n",
    "- название исключения (ZeroDivisionError);\n",
    "- файл, номер строки и сама строка с ошибкой;\n",
    "- название исключения повторяется и добавляется поясняющее сообщение division by zero.\n",
    "\n",
    "Если ошибка будет в другом, название исключения и поясняющее сообщение изменится:\n",
    "\n",
    "```\n",
    "university = {\"univ_name\": \"Finance\", \"city\": \"Moscow\"}  \n",
    "university[\"rating\"]\n",
    "---------------------------------------------------------------------\n",
    "KeyError                             Traceback (most recent call last)\n",
    "<ipython-input-6-22d4e579e046> in <module>\n",
    "      1 university = {\"univ_name\": \"Finance\", \"city\": \"Moscow\"}\n",
    "----> 2 university[\"rating\"]\n",
    "\n",
    "KeyError: 'rating'\n",
    "```\n",
    "В этом примере мы получили *KeyError* — отсутствующий ключ в словаре и сам ключ.\n",
    "\n",
    "<p class=\"header_4\">Задание</p>\n",
    "\n",
    "Назовите имя исключения по сообщению об ошибке:\n",
    "\n",
    "```\n",
    "-------------------------------------------------------------------\n",
    "FileNotFoundError                 Traceback (most recent call last)\n",
    "ipython-input-275-905b846ab02e in module\n",
    "      4     csv_file = open(\"random.csv\")\n",
    "      5 \n",
    "----> 6 open_imdb()\n",
    "      7 \n",
    "\n",
    "ipython-input-275-905b846ab02e in open_imdb()\n",
    "      2 \n",
    "      3 def open_imdb():\n",
    "----> 4     csv_file = open(\"random.csv\")\n",
    "      5 \n",
    "      6 open_imdb()\n",
    "\n",
    "FileNotFoundError: [Errno 2] No such file or directory: 'random.csv'\n",
    "```\n",
    "\n",
    "<p class=\"header_2\" style=\"text-align:center\"> Стэк вызова </p>\n",
    "\n",
    "В сообщении об ошибке указывается файл и номер строки, где она случилась. На самом деле, указывается стэк вызова (Traceback). Это путь, который проходит интерпретатор до того, как встретил ошибку. \n",
    "\n",
    "Пример: фрагмент программы генерирует таблички для шкафов определенного раздела литературы в библиотеке университета. Параметрами программы являются раздел литературы *partition* и последний номер шкафа *last_bookcase.*\n",
    "\n",
    "<img src=\"../Img/Error_message.png\" style=\"width:600px\">\n",
    "\n",
    "Мы вызвали функцию *library()*, которая воспользовалась *one_bookcase()*, где уже закралась ошибка. В сообщении об ошибке видим список всех наших функций с их местоположением и кодом, приведённый в том порядке, как мы их вызывали:\n",
    "\n",
    "- вызов library() на 12-й строчке;\n",
    "- вызов one_bookcase() внутри library на 9-й;\n",
    "- ошибка на 3-й строчке;\n",
    "- интерпретатор получил число там, где ожидал строку.\n",
    "\n",
    "Мы пытаемся сложить строку *string* с числом *number*. Достаточно поменять это сложение на форматированную строку, чтобы программа корректно заработала."
   ]
  },
  {
   "cell_type": "code",
   "execution_count": 2,
   "metadata": {},
   "outputs": [
    {
     "data": {
      "text/plain": [
       "['Бухгалтерский учёт, шкаф № 1',\n",
       " 'Бухгалтерский учёт, шкаф № 2',\n",
       " 'Бухгалтерский учёт, шкаф № 3']"
      ]
     },
     "execution_count": 2,
     "metadata": {},
     "output_type": "execute_result"
    }
   ],
   "source": [
    "# Один шкаф\n",
    "def one_bookcase(string, number):\n",
    "    return f\"{string}, шкаф № {number}\"\n",
    "  \n",
    "# Все шкафы\n",
    "def library(partition, last_bookcase):\n",
    "    bookcases = []\n",
    "    for i in range(last_bookcase):\n",
    "        bookcases.append(one_bookcase(partition, i+1))\n",
    "        \n",
    "    return bookcases\n",
    "\n",
    "library(\"Бухгалтерский учёт\", 3)"
   ]
  },
  {
   "cell_type": "markdown",
   "metadata": {},
   "source": [
    "<p class=\"header_4\">Задание</p>\n",
    "\n",
    "Приведён стэк вызова из сообщения об ошибке. Назовите имя функции, внутри которой произошла ошибка:\n",
    "```\n",
    "--------------------------------------------------------------------\n",
    "IndexError                         Traceback (most recent call last)\n",
    "ipython-input-1-70bd89baa4df in module()\n",
    "      6     print(ice_creams[3])\n",
    "      7\n",
    "----> 8 favorite_ice_cream()\n",
    "\n",
    "ipython-input-1-70bd89baa4df in favorite_ice_cream()\n",
    "      4         \"vanilla\", \"strawberry\"\n",
    "      5     ]\n",
    "----> 6     print(ice_creams[3])\n",
    "      7\n",
    "      8 favorite_ice_cream()\n",
    "\n",
    "IndexError: list index out of range\n",
    "```\n",
    "\n",
    "<p class=\"header_2\"> Зачем такой стэк </p>\n",
    "\n",
    "Зачем нам предыдущие шаги в стэке вызова, если в конце показывается истинное место ошибки. Причины две:\n",
    "\n",
    "1. Одна и та же функция может вызваться в разных местах с разными данными: полный путь помогает понять контекст.\n",
    "2. Вы пользуетесь сторонней библиотекой и некорректно применили функцию из неё, тогда ошибка может уйти глубже и в конце стэка будут показываться нерелеватные внутренности библиотеки, а нужная функция будет в середине стэка.\n",
    "\n",
    "<p class=\"header_2\"> Что такое исключение </p>\n",
    "\n",
    "При ошибках Python генерирует исключения: разберёмся, что это такое и откуда они берутся. Исключения — это ещё один тип данных, как строки или числа."
   ]
  },
  {
   "cell_type": "code",
   "execution_count": 21,
   "metadata": {},
   "outputs": [
    {
     "name": "stdout",
     "output_type": "stream",
     "text": [
      "<class 'str'>\n",
      "<class 'int'>\n",
      "<class 'list'>\n",
      "<class 'FileNotFoundError'>\n",
      "<class 'ZeroDivisionError'>\n",
      "<class 'NameError'>\n"
     ]
    }
   ],
   "source": [
    "print(type(\"University\"))  \n",
    "print(type(42))\n",
    "print(type([\"a\",\"b\",\"c\"]))\n",
    "\n",
    "print(type(FileNotFoundError()))\n",
    "print(type(ZeroDivisionError()))\n",
    "print(type(NameError()))"
   ]
  },
  {
   "cell_type": "markdown",
   "metadata": {},
   "source": [
    "Список часто встречающихся встроенных ошибок Python можно посмотреть здесь: https://www.tutorialsteacher.com/python/error-types-in-python\n",
    "\n",
    "Когда программа встречает некорректные ситуации, она выбрасывает исключения. Для базовых случаев это делает сам интерпретатор, но могут делать и авторы библиотек и программ в определённых ситуациях. Для этого есть специальный синтаксис `raise Exception()`\n",
    "\n",
    "<img src=\"../Img/RaiseRuntimeError.png\">"
   ]
  },
  {
   "cell_type": "markdown",
   "metadata": {},
   "source": [
    "Зачем специально генерировать ошибку в собственном коде? Для того, чтобы писать более предсказуемый код, во многих ситуациях выбросить ошибку лучше, чем работать с некорректными данными. Выбрасывание исключений является повсеместной практикой в Python и других языках программирования.\n",
    "\n",
    "Пример: вот функция, которая сортирует деревья:"
   ]
  },
  {
   "cell_type": "code",
   "execution_count": 5,
   "metadata": {},
   "outputs": [
    {
     "name": "stdout",
     "output_type": "stream",
     "text": [
      "a tree with leaves\n"
     ]
    }
   ],
   "source": [
    "def tree_type(tree_name):\n",
    "    if tree_name == \"birch\": # берёза\n",
    "        print(\"a tree with leaves\") # листья\n",
    "    elif tree_name == \"pine\": # сосна\n",
    "        print(\"a tree with needles\") # иголки\n",
    "\n",
    "tree_type(\"birch\")"
   ]
  },
  {
   "cell_type": "markdown",
   "metadata": {},
   "source": [
    "Что произойдёт, если мы вызовем эту функцию для платана (sycamore)?"
   ]
  },
  {
   "cell_type": "code",
   "execution_count": 6,
   "metadata": {},
   "outputs": [],
   "source": [
    "tree_type(\"sycamore\")"
   ]
  },
  {
   "cell_type": "markdown",
   "metadata": {},
   "source": [
    "Ничего не произошло, название дерева отсутствует и функция ничего не вернула. Такая ситуация опасна тем, что мы думаем, что если ошибки нет, то всё в порядке. Однако в данном случае отсутстве отклика от функции может привести к принятию неверного решения в дальнейшем.\n",
    "\n",
    "Более корректно было бы выбросить ошибку:\n",
    "\n",
    "<img src=\"../Img/Error_message2.png\" style=\"width:600px\">"
   ]
  },
  {
   "cell_type": "markdown",
   "metadata": {},
   "source": [
    "Здесь мы выбросили \"Ошибку значения\" (ValueError), но ошибка не информативная. Мы можем добавить поясняющее сообщение.\n",
    "\n",
    "<img src=\"../Img/Error_message3.png\" style=\"width:600px\">"
   ]
  },
  {
   "cell_type": "markdown",
   "metadata": {},
   "source": [
    "В последней строчке добавилось пояснение, что мы передали название неизвестного дерева. В Python достаточно много встроенных типов исключений. Вы можете посмотреть их в <a href=https://docs.python.org/3/library/exceptions.html>документации</a> к языку и выбрать подходящий по смыслу для вашей ситуации.\n",
    "\n",
    "<p class=\"header_4\"> Задание </p>\n",
    "\n",
    "Напишите текст, который выведется на последней строке при исполнении программы\n",
    "```\n",
    "def preprocess_data(data, mode):\n",
    "    if mode == \"to_number\":\n",
    "        return [float(value) for value in data]\n",
    "    elif mode == \"to_str\":\n",
    "        return [str(value) for value in data]\n",
    "    else:\n",
    "        raise ValueError(\"Incorrect mode\")\n",
    "        \n",
    "preprocess_data({\"price\": 100}, \"to_array\")\n",
    "```"
   ]
  },
  {
   "cell_type": "code",
   "execution_count": null,
   "metadata": {},
   "outputs": [],
   "source": [
    "# Ваш ответ здесь\n",
    "\n"
   ]
  },
  {
   "cell_type": "markdown",
   "metadata": {},
   "source": [
    "<p class=\"header_4\"> Задание </p>\n",
    "\n",
    "Определите функцию *check_server()*, которая принимает на вход переменную *mode*.\n",
    "\n",
    "- Если mode имеет значение \"memory\", программа должна вернуть строку \"Memory is ok\".\n",
    "- Если mode имеет значение \"connection\", программа должна вернуть строку \"Connection is ok\".\n",
    "- Для остальных случаев программа должна выбросить исключение ValueError."
   ]
  },
  {
   "cell_type": "code",
   "execution_count": 48,
   "metadata": {},
   "outputs": [],
   "source": [
    "# Ваш код здесь\n",
    "\n"
   ]
  },
  {
   "cell_type": "markdown",
   "metadata": {},
   "source": [
    "<p class=\"large_text\" style=\"text-align:center\"> 2. Обработка исключений </p>\n",
    "\n",
    "### Что такое исключение\n",
    "\n",
    "Мы научились выбрасывать исключения, и потенциально это ломает программу. Очевидный способ избавиться от этого — исправить ошибку, но бывают ситуации, когда мы не вполне контролируем данные, например, пользовательский ввод или большая база данных с небольшим количеством искаженных данных. Изредка мы всё-таки будем получать исключения, и нам надо с этим как-то работать.\n",
    "\n",
    "Для этой цели мы можем воспользоваться блоком отработки исключений — *try-except*. Он позволяет отрабатывать исключения, не прерывая хода программы. Без блока *try-except* в примере мы бы получили *KeyError*, здесь же мы печатаем строку *Ой, ключ не найден* и продолжаем выполнение программы.\n",
    "\n",
    "    dictionary = {}\n",
    "    try:\n",
    "        dictionary[\"no_key\"]\n",
    "    except:\n",
    "        print(\"Oops, key not found\")\n",
    "      \n",
    "    print(\"End of program\")\n",
    "    # => Oops, key not found\n",
    "    # => End of program\n",
    "\n",
    "Если более формально, то мы пробуем выполнить часть программы, которая находится внутри *try*. Если эта часть кода выбрасывает исключение, то мы сразу переходим к выполнению части внутри *except*. Если же исключение не выбрасывается, то мы пропускаем часть внутри *except*. В любом случае мы выполняем программу дальше, как обычно.\n",
    "\n",
    "<p class=\"header_4\">Задание</p>\n",
    "\n",
    "<p class=\"header_6\"> 2.1. Try-except 1 </p>\n",
    "\n",
    "Что выведет этот блок try-except?\n",
    "```\n",
    "try:\n",
    "    print(\"Inside try block\")\n",
    "except:\n",
    "    print(\"Inside except block\")\n",
    "```\n",
    "\n",
    "\n",
    "<p class=\"header_6\"> 2.2. Try-except 2 </p>\n",
    "\n",
    "Что выведет этот блок try-except?\n",
    "```\n",
    "try:\n",
    "    4 + \"b\"\n",
    "    print(\"Inside try block\")\n",
    "except:\n",
    "    print(\"Inside except block\")\n",
    "```\n",
    "\n",
    "<p class=\"large_text\" style=\"text-align:center\"> 3. Осознанная обработка исключений </p>\n",
    "\n",
    "Общая идея использования try-except такая:\n",
    "\n",
    "- вы знаете, что у вас может возникнуть исключение, и не можете его полностью избежать;\n",
    "- вы \"отлавливаете\" эти исключения, а в блок *except* помещаете логику, которая позволит вам из этой ситуации корректно выйти.\n",
    "\n",
    "Когда мы вызываем *raise*, то делаем подачу: тут какие-то не такие данные, нужно исправить. Когда мы обрабатываем исключения через *try-except*, то принимаем: да, данные неидеальные, но я об этом подумал. Проблема в том, что с обычным *try-except* можно \"отловить\" не только те исключения, на которые мы рассчитывали. \n",
    "\n",
    "Посмотрим на примере: у нас есть программа, которая отрабатывает очень большую базу данных, и мы бы хотели, чтобы была возможность корректно прервать её с клавиатуры. Код мог бы выглядеть как-то так:\n",
    "```\n",
    "try:  \n",
    "    # запускаем программу отработки базы данных  \n",
    "    process(db)   \n",
    "except:  \n",
    "    # если с клавиатуры пришло прерывание, то корректно останавливаем процесс  \n",
    "    gently_close(db)\n",
    "```\n",
    "При остановке с клавиатуры мы получаем исключение *KeyInterrupt*, так что мы идём в блок *except* и корректно закрываем базу данных. Проблема в том, что *except* \"отловит\" и другие исключения, например, ошибку отсутствующего ключа или таймаута, что усложнит для нас обнаружение и исправление этих ошибок. На этот случай *try-except* позволяет указывать, какое именно исключение мы отлавливаем.\n",
    "\n",
    "```\n",
    "try:  \n",
    "    process(db)   \n",
    "except KeyInterrupt:  # обратите внимание, что мы добавили имя исключения после except  \n",
    "    gently_close(db)\n",
    "```\n",
    "\n",
    "Так мы не пропустим случайно неожиданную ошибку. Давайте посмотрим на ещё один пример для закрепления синтаксиса:\n",
    "\n",
    "```\n",
    "dictionary = {}  \n",
    "try:  \n",
    "    dictionary[\"no_key\"]  \n",
    "except KeyError:  \n",
    "    print(\"Oops, key not found\")  \n",
    "# => Oops, key not found  \n",
    "  \n",
    "  \n",
    "dictionary = {}  \n",
    "try:  \n",
    "    dictionary[\"no_key\"]  \n",
    "except IOError:  \n",
    "    print(\"Oops, key not found\")  \n",
    "# ---------------------------------------------------------------------------  \n",
    "# KeyError                                  Traceback (most recent call last)  \n",
    "# <ipython-input-90-56e08e34101d> in <module>  \n",
    "#       8 dictionary = {}  \n",
    "#       9 try:  \n",
    "# ---> 10     dictionary[\"no_key\"]  \n",
    "#      11 except IOError:  \n",
    "#      12     print(\"Oops, key not found\")  \n",
    "  \n",
    "# KeyError: 'no_key\n",
    "```\n",
    "Во втором случае мы ожидали IOError, но исключение было KeyError, поэтому программа прервалась с ошибкой. Это упростит исправление ошибки.\n",
    "\n",
    "Подведем итог: конкретное исключение в *try-except* нужно указывать, чтобы не пропустить случайно исключение, про которое мы не знаем и упростить исправление ошибки."
   ]
  },
  {
   "cell_type": "markdown",
   "metadata": {},
   "source": [
    "<p class=\"large_text\" style=\"text-align:center\"> 4. Иерархия исключений </p>\n",
    "\n",
    "Исключения в Python имеют иерархию: имеются более общие и более специфичные исключения. Вот график исключений:\n",
    "\n",
    "<img src=\"../Img/exception_hierarchy.png\"/>\n",
    "\n",
    "Здесь мы видим, что KeyError и IndexError являются подмножеством LookupError, которая является подмножеством Exception. На практике это имеет следующее значение: если мы укажем исключение верхнего уровня, то \"отловятся\" все дочерние, но не наоборот.\n",
    "\n",
    "Напишем функцию, которая может обращаться и к спискам, и к словарям при этом не выбрасывая исключение для несуществующих индексов/ключей   \n",
    "\n",
    "    def safe_element(collection, place):  \n",
    "        try:  \n",
    "            return(collection[place])  \n",
    "        except LookupError:  \n",
    "            print(\"Key or index not found\")  \n",
    "      \n",
    "    users = [\"Pavel\", \"Elena\", \"Sergey\"]  \n",
    "    safe_element(users, 1)  \n",
    "    # => 'Elena'  \n",
    "    safe_element(users, 3)  \n",
    "    # => 'Key or index not found'   \n",
    "\n",
    "    height = {\"birch\": 10, \"pine\": 20}\n",
    "    safe_element(height, \"birch\")\n",
    "    # => 10\n",
    "    safe_element(height, \"sycamore\")\n",
    "    # => 'Key or index not found'\n",
    "\n",
    "Желательно указывать наиболее специфичное исключение. Полную иерархию можно посмотреть в <a href=\"https://docs.python.org/2/library/exceptions.html#exception-hierarchy\">документации</a>.\n",
    "\n",
    "<p class=\"header_4\">Задание</p>\n",
    "\n",
    "<p class=header_6> 4.1. Родители ZeroDivision </p>\n",
    "\n",
    "Назовите одно из исключений, для которого *ZeroDivisionError* является дочерним.\n",
    "\n",
    "<p class=header_6> 4.2. safe_sum </p>\n",
    "\n",
    "Напишите программу, которая реализует безопасное сложение двух объектов $x$ и $y$.\n",
    "\n",
    "Если объекты не могут быть сложены, функция должна:\n",
    "\n",
    "- Отловить TypeError\n",
    "- Вывести на экран \"Can't sum x and y\", где x и y - переданные числа\n",
    "- Вернуть 0\n",
    "\n",
    "```\n",
    "safe_sum(1, 2)\n",
    "#=> 3\n",
    "\n",
    "safe_sum(5, 'a')\n",
    "# => Can't sum 5 and a\n",
    "# 0\n",
    "```\n"
   ]
  },
  {
   "cell_type": "code",
   "execution_count": 47,
   "metadata": {},
   "outputs": [],
   "source": [
    "# Ваш код здесь\n",
    "\n"
   ]
  },
  {
   "cell_type": "markdown",
   "metadata": {},
   "source": [
    "<p class=\"large_text\" style=\"text-align:center\"> 5. Детали try-except </p>\n",
    "\n",
    "Мы рассмотрели базовый синтаксис *try-except*, однако у него есть ещё несколько вариаций. Они не часто встречаются на практике. Иногда в блоке *except* нам нужен доступ к самому объекту исключения, например, мы хотим получить поясняющее сообщение и вывести его на экран, но при этом продолжить программу дальше. Мы можем это сделать с помощью ключевого слова *'as'*, за которым идёт имя новой переменной.\n",
    "```\n",
    "try:  \n",
    "    5/0  \n",
    "except ZeroDivisionError as zero_error:  \n",
    "    # здесь в zero_error мы получаем сам объект исключения  \n",
    "    # print как раз выведет его поясняющее сообщение  \n",
    "    print(zero_error)  \n",
    "  \n",
    "print(\"Program ends correctly\")  \n",
    "  \n",
    "# => division by zero  \n",
    "# => Program ends correctly\n",
    "```\n",
    "\n",
    "Ещё один распространённый **паттерн** — это то, что мы делаем какое-то промежуточное действие, а потом перевыбрасываем исключение.\n",
    "```\n",
    "# Пусть у нас есть функция, которая шлёт емейл разработчику об ошибке  \n",
    "def notify_admin(error):  \n",
    "    print(\"The administrator has been e-mailed about this\", error)  \n",
    "      \n",
    "value = \"poem\"  \n",
    "try:  \n",
    "    digitized = int(value)  \n",
    "except ValueError as digitized_error:  \n",
    "    notify_admin(digitized_error)  \n",
    "    raise digitized_error  \n",
    "      \n",
    "# => The administrator has been e-mailed about this invalid literal for int() with base 10: 'poem'  \n",
    "# ---------------------------------------------------------------------------  \n",
    "# ValueError                                Traceback (most recent call last)  \n",
    "# <ipython-input-121-3fd4cd869d2d> in <module>  \n",
    "#       8 except ValueError as digitized_error:  \n",
    "#       9     notify_admin(digitized_error)  \n",
    "# ---> 10     raise digitized_error  \n",
    "#      11   \n",
    "#      12   \n",
    "  \n",
    "# <ipython-input-121-3fd4cd869d2d> in <module>  \n",
    "#       5 value = \"poem\"  \n",
    "#       6 try:  \n",
    "# ----> 7     digitized = int(value)  \n",
    "#       8 except ValueError as digitized_error:  \n",
    "#       9     notify_admin(digitized_error)  \n",
    "  \n",
    "# ValueError: invalid literal for int() with base 10: 'poem'\n",
    "```\n",
    "Обратите внимание: мы перехватили ошибку и отправили админу стандартное сообщение об ошибке, затем мы вывели на печать сообщение о том, что админ уведомлен и также о том, какое именно сообщение админу направлено, затем только мы вызвали явно эту же ошибку.\n",
    "\n",
    "Другая полезная вещь, что для одного *try* можете писать более одного *except* на разные исключения.\n",
    "```\n",
    "try:  \n",
    "    # открываем файл и считываем строку  \n",
    "    data_file = open(\"valuable_data.txt\")  \n",
    "    s = data_file.readline()  \n",
    "    # пробуем преобразовать её в число  \n",
    "    i = float(s.strip())  \n",
    "except OSError as err:  \n",
    "    # если файла нет или его не удаётся прочитать, мы получил ошибку операционной системы   \n",
    "    print(\"OS error: {0}\".format(err))  \n",
    "except ValueError:  \n",
    "    # если данные не преобразуется в число, мы получим ValueError  \n",
    "    print(\"Could not convert data to float\")  \n",
    "  \n",
    "# => OS error: [Errno 2] No such file or directory: 'valuable_data.txt'\n",
    "```\n",
    "У *try-except* есть блоки *else* и *finally*, первый выполняется в случае, если мы не встретили исключение в *try*, используется в основном для чуть более чистого кода. *Finally* выполняется в любом случае, даже если возникло непредвиденное исключение или выход с помощью *return*. Обычно используется для корректного освобождения ресурсов, например, закрытия файлов."
   ]
  }
 ],
 "metadata": {
  "kernelspec": {
   "display_name": "Python 3 (ipykernel)",
   "language": "python",
   "name": "python3"
  },
  "language_info": {
   "codemirror_mode": {
    "name": "ipython",
    "version": 3
   },
   "file_extension": ".py",
   "mimetype": "text/x-python",
   "name": "python",
   "nbconvert_exporter": "python",
   "pygments_lexer": "ipython3",
   "version": "3.9.12"
  }
 },
 "nbformat": 4,
 "nbformat_minor": 4
}
